Another git process seems to be running in this repository, e.g.
an editor opened by 'git commit'. Please make sure all processes
are terminated then try again. If it still fails, a git process
may have crashed in this repository earlier:
remove the file manually to continue.

solution
PS D:\Income_Prediction> rm .git/index.lock

----------------------------------------------------------

Traceback (most recent call last):
  File "C:\python37\lib\runpy.py", line 196, in _run_module_as_main
    return _run_code(code, main_globals, None,
  File "C:\python37\lib\runpy.py", line 86, in _run_code
    exec(code, run_globals)
  File "D:\Income_Prediction\main.py", line 2, in <module>
    from income_pred.logger import logging
ImportError: cannot import name 'logging' from 'income_pred.logger' (D:\Income_Prediction\income_pred\logger\__init__.py)

solution:
deleted logger folder.

----------------------------------------------------------
Traceback (most recent call last):
  File "C:\python37\lib\site-packages\pandas\core\indexes\base.py", line 3802, in get_loc
    return self._engine.get_loc(casted_key)
  File "pandas\_libs\index.pyx", line 138, in pandas._libs.index.IndexEngine.get_loc
  File "pandas\_libs\index.pyx", line 165, in pandas._libs.index.IndexEngine.get_loc
  File "pandas\_libs\hashtable_class_helper.pxi", line 5745, in pandas._libs.hashtable.PyObjectHashTable.get_item
  File "pandas\_libs\hashtable_class_helper.pxi", line 5753, in pandas._libs.hashtable.PyObjectHashTable.get_item
KeyError: 'education.num'

The above exception was the direct cause of the following exception:

Traceback (most recent call last):
  File "D:\Income_Prediction\income_pred\components\data_transformation.py", line 44, in remove_outliers_IQR
    Q1 = df[col].quantile(0.25)
  File "C:\python37\lib\site-packages\pandas\core\frame.py", line 3807, in __getitem__
    indexer = self.columns.get_loc(key)
  File "C:\python37\lib\site-packages\pandas\core\indexes\base.py", line 3804, in get_loc
    raise KeyError(key) from err
KeyError: 'education.num'

During handling of the above exception, another exception occurred:

Traceback (most recent call last):
  File "D:\Income_Prediction\income_pred\components\data_transformation.py", line 66, in initiate_data_transformation
    self.remove_outliers_IQR(col=col,df=train_data)
  File "D:\Income_Prediction\income_pred\components\data_transformation.py", line 55, in remove_outliers_IQR
    raise CustomException(e,sys)
income_pred.exception.CustomException: Error Occured in python script name [D:\Income_Prediction\income_pred\components\data_transformation.py] line number [44] error message ['education.num']

During handling of the above exception, another exception occurred:

Traceback (most recent call last):
  File "C:\python37\lib\runpy.py", line 196, in _run_module_as_main
    return _run_code(code, main_globals, None,
  File "C:\python37\lib\runpy.py", line 86, in _run_code
    exec(code, run_globals)
  File "D:\Income_Prediction\income_pred\components\data_ingestion.py", line 52, in <module>
    train_arr,test_arr, _ = data_transformation.initiate_data_transformation(train_data_path,test_data_path)
  File "D:\Income_Prediction\income_pred\components\data_transformation.py", line 99, in initiate_data_transformation
    raise CustomException(e,sys)
income_pred.exception.CustomException: Error Occured in python script name [D:\Income_Prediction\income_pred\components\data_transformation.py] line number [66] error message [Error Occured in python script name [D:\Income_Prediction\income_pred\components\data_transformation.py] line number [44] error message ['education.num']]

Solution:
In utils.py add this lone - os.makedirs(dir_path,exist_ok=True)
 
----------------------------------------------------------

Best Model Found, Model Name is: Random Forest,Accuracy_Score: 0.7864167178856791


Traceback (most recent call last):
  File "C:\python37\lib\site-packages\flask\app.py", line 2551, in __call__
    return self.wsgi_app(environ, start_response)
  File "C:\python37\lib\site-packages\flask\app.py", line 2531, in wsgi_app
    response = self.handle_exception(e)
  File "C:\python37\lib\site-packages\flask\app.py", line 2528, in wsgi_app
    response = self.full_dispatch_request()
  File "C:\python37\lib\site-packages\flask\app.py", line 1825, in full_dispatch_request
    rv = self.handle_user_exception(e)
  File "C:\python37\lib\site-packages\flask\app.py", line 1823, in full_dispatch_request
    rv = self.dispatch_request()
  File "C:\python37\lib\site-packages\flask\app.py", line 1799, in dispatch_request
    return self.ensure_sync(self.view_functions[rule.endpoint])(**view_args)
  File "D:\Income_Prediction\main.py", line 21, in prediction_data
    return render_template('home.html')
  File "C:\python37\lib\site-packages\flask\templating.py", line 146, in render_template
    template = app.jinja_env.get_or_select_template(template_name_or_list)
  File "C:\python37\lib\site-packages\jinja2\environment.py", line 1081, in get_or_select_template
    return self.get_template(template_name_or_list, parent, globals)
  File "C:\python37\lib\site-packages\jinja2\environment.py", line 1010, in get_template
    return self._load_template(name, globals)
  File "C:\python37\lib\site-packages\jinja2\environment.py", line 969, in _load_template
    template = self.loader.load(self, name, self.make_globals(globals))
  File "C:\python37\lib\site-packages\jinja2\loaders.py", line 126, in load
    source, filename, uptodate = self.get_source(environment, name)
  File "C:\python37\lib\site-packages\flask\templating.py", line 62, in get_source
    return self._get_source_fast(environment, template)
  File "C:\python37\lib\site-packages\flask\templating.py", line 98, in _get_source_fast
    raise TemplateNotFound(template)
jinja2.exceptions.TemplateNotFound: home.html

solution - make home.html