Another git process seems to be running in this repository, e.g.
an editor opened by 'git commit'. Please make sure all processes
are terminated then try again. If it still fails, a git process
may have crashed in this repository earlier:
remove the file manually to continue.

solution
PS D:\Income_Prediction> rm .git/index.lock

----------------------------------------------------------

Traceback (most recent call last):
  File "C:\python37\lib\runpy.py", line 196, in _run_module_as_main
    return _run_code(code, main_globals, None,
  File "C:\python37\lib\runpy.py", line 86, in _run_code
    exec(code, run_globals)
  File "D:\Income_Prediction\main.py", line 2, in <module>
    from income_pred.logger import logging
ImportError: cannot import name 'logging' from 'income_pred.logger' (D:\Income_Prediction\income_pred\logger\__init__.py)

solution:
deleted logger folder.

----------------------------------------------------------
Traceback (most recent call last):
  File "C:\python37\lib\site-packages\pandas\core\indexes\base.py", line 3802, in get_loc
    return self._engine.get_loc(casted_key)
  File "pandas\_libs\index.pyx", line 138, in pandas._libs.index.IndexEngine.get_loc
  File "pandas\_libs\index.pyx", line 165, in pandas._libs.index.IndexEngine.get_loc
  File "pandas\_libs\hashtable_class_helper.pxi", line 5745, in pandas._libs.hashtable.PyObjectHashTable.get_item
  File "pandas\_libs\hashtable_class_helper.pxi", line 5753, in pandas._libs.hashtable.PyObjectHashTable.get_item
KeyError: 'education.num'

The above exception was the direct cause of the following exception:

Traceback (most recent call last):
  File "D:\Income_Prediction\income_pred\components\data_transformation.py", line 44, in remove_outliers_IQR
    Q1 = df[col].quantile(0.25)
  File "C:\python37\lib\site-packages\pandas\core\frame.py", line 3807, in __getitem__
    indexer = self.columns.get_loc(key)
  File "C:\python37\lib\site-packages\pandas\core\indexes\base.py", line 3804, in get_loc
    raise KeyError(key) from err
KeyError: 'education.num'

During handling of the above exception, another exception occurred:

Traceback (most recent call last):
  File "D:\Income_Prediction\income_pred\components\data_transformation.py", line 66, in initiate_data_transformation
    self.remove_outliers_IQR(col=col,df=train_data)
  File "D:\Income_Prediction\income_pred\components\data_transformation.py", line 55, in remove_outliers_IQR
    raise CustomException(e,sys)
income_pred.exception.CustomException: Error Occured in python script name [D:\Income_Prediction\income_pred\components\data_transformation.py] line number [44] error message ['education.num']

During handling of the above exception, another exception occurred:

Traceback (most recent call last):
  File "C:\python37\lib\runpy.py", line 196, in _run_module_as_main
    return _run_code(code, main_globals, None,
  File "C:\python37\lib\runpy.py", line 86, in _run_code
    exec(code, run_globals)
  File "D:\Income_Prediction\income_pred\components\data_ingestion.py", line 52, in <module>
    train_arr,test_arr, _ = data_transformation.initiate_data_transformation(train_data_path,test_data_path)
  File "D:\Income_Prediction\income_pred\components\data_transformation.py", line 99, in initiate_data_transformation
    raise CustomException(e,sys)
income_pred.exception.CustomException: Error Occured in python script name [D:\Income_Prediction\income_pred\components\data_transformation.py] line number [66] error message [Error Occured in python script name [D:\Income_Prediction\income_pred\components\data_transformation.py] line number [44] error message ['education.num']]

Solution:
In utils.py add this lone - os.makedirs(dir_path,exist_ok=True)
 
----------------------------------------------------------